Workbook

Sheet Plurmits-All Plurmits
A1: Plurmit | B1: Department | C1: Annual volume of submissions | D1: Does this plurmit apply to businesses? | E1: Online Status [Normalized] | F1: Worth Integrating or Mentioning? | G1: Notes on integration/mention analysis | H1: Is it Integrated or mentioned yet? | I1: Link to CMS if mentioned *TLC: Don't use this column: use the Consumer Affairs Licenses column | J1: Relevant ADO tickets to Integration or Mention (Optional) | K1: Where is it (going to be) located? [MUNI] | L1: Does this still need to be implemented for Oscars? [MUNI] | M1: Does it apply to Business.NJ.gov users? [MUNI] | N1: Mentioned on Business.NJ.gov? [MUNI] | O1: Industry/Sector Notes [MUNI] | P1: Municipality or LEA dependent? [MUNI] | Q1: Can it be integrated? (R and/or RW) [MUNI] | R1: Agency/Division | S1: Source | T1: Link/URL to viewable/ downloadable form (e.g., PDF) | U1: If applicable: Link/URL to website where the form can be completed and submitted online | V1: OFFICIAL FORM NUMBER (IF ASSIGNED) | W1: ONLINE FILING Y/N FROM PAST RESPONSE | X1: How does the user find the application form? (Online/Phone/Mail/In Person) | Y1: How does the user submit the form? (Online/Mail/Email/In Person) | Z1: If this form is online, what plaform/service is it hosted on? | AA1: If there is a fee, what is the fee to submit this form? | AB1: If there is a fee, what is the fee to submit this form? [Removed nulls] | AC1: If there is a fee, what is the fee to submit this form? [Normalized] | AD1: If the form needs the involvement of a notary/inspector/consultant/certified third party to be completed, please indicate the third party. | AE1: If the form needs the involvement of a notary/inspector/consultant/certified third party to be completed, please indicate the third party. [Normalized] | AF1: If there is a regulation or unsupported requirement (engineering drawing) preventing this form from being moved online, what is it? | AG1: If there is a regulation or unsupported requirement (engineering drawing) preventing this form from being moved online, what is it? [Normalized] | AH1: If it has some, what is the FAQ/copy/instructions for this form or group of forms? (provide URL if possible) | AI1: ➡️ ADDITIONAL NOTES | AJ1: Make an in-person request | AK1: On average, what percentage of form submissions end up rejected or sent back with errors? | AL1: What is the average processing time for this form? (In terms of hours:days) | AM1: The form is trackable online | AN1: Users receive an SMS | AO1: Make a request by calling our office | AP1: What is the total number of staff who handle: the review of, or approval/rejection of this form? | AQ1: Does this form have a regulatory timeframe? | AR1: Make a request through email/chat service | AS1: Do you notify users about information related to the status of their form? | AT1: What are the common reasons that forms are rejected? | AU1: For Column G "annual volume of form submissions," specify date range if complete data for Aug 2021 - Aug 2020 is not available. | AV1: Is there a fee associated with the submission of the form? | AW1: What is the annual volume of form submissions? [Integer] (CA) | AX1: Top 30: Law & Public Safety Survey 2019 | AY1: Query Identifier (from Dev pull) | AZ1: MLO Profession (using Boomi) | BA1: Task Exists, Integration Needed by Dev (as of 10 May 2024) | BB1: Reinstatement | BC1: MLO License Type # | BD1: Renewal | BE1: Task in CMS (main license application) [ARCHIVED] | BF1: Obtained by | BG1: Dyn. Applic. Type | BH1: Applies to Business (not individual)? (Regina's guesses) [TLC] | BI1: Database/System | BJ1: Legalized Games Category | BK1: Assigned initial review [TLC] | BL1: Consumer Affairs Licenses in CMS | BM1: Notes Consumer Affairs [TLC] | BN1: Industry [MUNI] | BO1: Industry Sector [MUNI] | BP1: [ECO] - PLURmit Purpose | BQ1: [ECO] - DEP Media Area | BR1: [ECO] - Current URL | BS1: Total Number of Licensees | BT1: Relates to B.NJ Industry | BU1: [ECO] - PLURmit Type | BV1: [ECO] - DEP System | BW1: Business Activity & Equipment | BX1: Business Activity & Equipment 2
A2: Sales Tax | B2: Department of the Treasury | C2: 866606 | D2: Yes this is a business/shop plurmit | F2: High Priority Integration, lacking agency buy-in | G2: We would love to integrate but Treasury does not want to as of Aug 26 2024. This is technically for the quarterly taxes, while ST-51 is for monthly taxes. We also have this in the CMS that covers the monthly taxes: https://dev.account.business.nj.gov/mgmt/cms#/collections/filings/entries/st-51_451 | H2: Read | I2: https://dev.account.business.nj.gov/mgmt/cms#/collections/filings/entries/st-50_450 | R2: Division of Taxation | S2: 2021 Permit List | U2: https://www1.state.nj.us/TYTR_BusinessFilings/jsp/common/Login.jsp?taxcode=55 | V2: ST-50; ST-50B; ST-450; ST-450B | X2: Online,Phone | Y2: Online | Z2: DORES Web Portal & AXWAY (3rd party software vendor) | AJ2: Yes | AK2: Cannot provide rejection counts due to daily changes. | AL2: Instantaneous | AM2: Yes | AN2: No | AO2: Yes | AP2: DORES | AQ2: Yes | AR2: Yes | AS2: No | AT2: Registration, Data Integrity, Calculation | AU2: 2020 | AV2: No | BH2: Yes
A3: Annual Report | B3: Department of the Treasury | C3: 667592 | D3: Yes this is a business/shop plurmit | F3: Yes - High Priority Integration | G3: 2021 667592 2022 705533 2023 752488 2024 786413 | H3: Read | I3: https://dev.account.business.nj.gov/mgmt/cms#/collections/filings/entries/annual-report | K3: Evergreen | BH3: Yes
A4: Producer Company Appointment/Termination Fee | B4: Department of Banking and Insurance | C4: 467251 | D4: Yes, but primarily used by large businesses | E4: Submitted | F4: No | G4: out of scope for BizX, this is focused on large insurance companies rather than SMBs | H4: No | S4: Combined data from 2018 and 2021 | T4: www.nipr.com | W4: Y | X4: Online | Y4: Online | AC4: No | AE4: No | AG4: No | AI4: INS
A5: New Jersey Partnership Return Gross Income Tax | B5: Department of the Treasury | C5: 253286 | D5: Yes this is a business/shop plurmit | F5: Yes - High Priority Integration | G5: We would love to integrate but Treasury does not want to as of Aug 26 2024 | H5: Read | I5: https://dev.account.business.nj.gov/mgmt/cms#/collections/filings/entries/nj-1065 | R5: Division of Taxation | S5: 2021 Permit List | T5: https://nj.gov/treasury/taxation/prntpart.shtml | U5: https://www1.state.nj.us/TYTR_BusinessFilings/jsp/common/Login.jsp?taxcode=43 | V5: NJ-1065 | X5: Online | Y5: In Person,Online,Mail | Z5: DORES Web Portal & AXWAY (3rd party software vendor) | AJ5: Yes | AK5: Cannot provide rejection counts due to daily changes. | AL5: Instantaneous | AM5: Yes | AN5: No | AO5: Yes | AQ5: Yes | AR5: Yes | AS5: No | AT5: Registration, Data Integrity, Calculation | AU5: 2019 | AV5: No | BH5: Yes
A6: Statement of Estimated Tax for Corporations | B6: Department of the Treasury | C6: 208969 | D6: Yes this is a business/shop plurmit | F6: Yes - Mention but not Integrate | G6: We would love to integrate but Treasury does not want to as of Aug 26 2024 | H6: Read | I6: https://dev.account.business.nj.gov/mgmt/cms#/collections/filings/entries/cbt-150 | R6: Division of Taxation | S6: 2021 Permit List | T6: https://nj.gov/treasury/taxation/prntcbt.shtml | U6: https://www1.state.nj.us/TYTR_BusinessFilings/jsp/common/Login.jsp?taxcode=20 | V6: CBT-150 | X6: Online | Y6: Online | Z6: DORES Web Portal & AXWAY (3rd party software vendor) | AJ6: Yes | AK6: Cannot provide rejection counts due to daily changes. | AL6: Instantaneous | AM6: Yes | AN6: No | AO6: Yes | AQ6: Yes | AR6: Yes | AS6: No | AT6: Registration, Data Integrity, Calculation | AU6: 2019 | AV6: No | BH6: Yes
A7: Weights and Measures Device Registration Certification (Devices) | B7: Department of Law and Public Safety | C7: 188109 | D7: Yes this is a business/shop plurmit | E7: Available | F7: Yes - Mention but not Integrate | G7: We have access to some data on weights and measures, but it may be a challenge to discern how to use it without a walkthrough from Consumer Affairs | H7: Mentioned | S7: Combined data from 2018 and 2021 | T7: https://www.njconsumeraffairs.gov/OWM/Applications/Registration-Application-for-Commercial-Weighing-and-Measuring-Devices.pdf | W7: N | X7: In person,Mail,Online | Y7: In person,Mail | Z7: DCA Website | AA7: Varies based on type of device | AB7: Varies based on type of device | AC7: Yes | AE7: No | AG7: No | BH7: Yes | BK7: RL | BL7: "weights-measures-registration - Register a Scale, Meter, or Other Weighing and Measuring Device for Your Business"
A8: Saltwater Angler - Individual Registration | B8: Department of Environmental Protection | C8: 160000 | D8: No, this is for municipalities or residents but not businesses | E8: Submitted | F8: No | G8: Called two charter boat companies in NJ, and customers are covered under the Captain's Saltwater Registry - For Hire Vessel registry record - Also connected with Katie from the NJDEP - Fish & Wildlife and stated there are ~1050 for-hire registrations this year - Bait and tackle shop employees could fall under retail, but unclear if that means the owner of the shop needs this permit. Even if so, this seems like a rare use case. | H8: N/A | S8: Combined data from 2018 and 2021 | T8: https://www.nj.gov/dep/online/ | U8: https://www.nj.gov/dep/online/ | X8: Online | Y8: Online | Z8: DEP Online | AC8: No | AE8: No | AG8: No | AH8: https://www.nj.gov/dep/online/ | BP8: From site: The New Jersey Department of Environmental Protection established the New Jersey Saltwater Recreational Registry Program to exempt saltwater recreational anglers fishing in New Jersey’s marine and tidal waters from the federal registry and the $15.00 federal registration fee imposed in 2011. The Department of Environmental Protection (DEP) implemented the New Jersey Saltwater Recreational Registry Program (NJSRRP) effective May 4, 2011 through Administrative Order No. 2011-05 . Who Needs to Register? NOTE: Anglers with a valid registration with the National Saltwater Angler Registry or have a valid license from another exempted state are required to register (for free) with the NJ Saltwater Recreational Registry Program. Registration with NJ will exempt you from having to register with the National Saltwater Angler Registry. Individual saltwater anglers ages 16 and older MUST register if ANY of the following criteria are met: - Recreationally fish with a hand line or rod and line, spearfish or fish by hand - Recreationally fish in the marine and fresh tidal waters of the State of New Jersey - Recreationally fish in marine waters outside the State of New Jersey but land the catch in New Jersey Individual saltwater anglers are EXEMPT from registering if either of the following apply: - Under the age of 16 - Solely fish on for-hire (party and charter) vessels that are registered with the New Jersey Saltwater Recreational Registry Program For-hire vessel owners/operators MUST register if: - Carry individuals who engage in recreational fishing in the marine and fresh tidal waters of the State of New Jersey OR - Carry individuals who engage in recreational fishing in the marine waters outside the State of New Jersey but land their catch in New Jersey From chat GPT: In New Jersey, specific businesses require a Saltwater Angler registration to legally engage in saltwater fishing activities. These businesses include: 1. Charter Boats and Party Boats: Companies offering chartered fishing trips or party boat services where patrons pay to fish in New Jersey's marine and estuarine waters. 2. Tackle Shops: Retailers that sell fishing equipment and may provide guidance or services related to saltwater fishing. 3. Marinas: Facilities that offer boat docking, storage, and other services for recreational fishing vessels. 4. Fishing Guides: Professional guides who lead fishing expeditions for clients in saltwater areas. The following types of businesses and their associated individuals require individual Saltwater Angler registration if they engage in recreational saltwater fishing: 1. Charter and Party Boat Operators: Captains and crew members who participate in fishing activities on charter or party boats. 2. Fishing Guides: Individuals who provide professional fishing guide services for recreational fishing in saltwater. 3. Commercial Fishermen Engaged in Recreational Fishing: Individuals who typically work in commercial fishing but also engage in recreational saltwater fishing. 4. Bait and Tackle Shop Employees: Employees who fish recreationally and may assist customers with fishing-related activities and guidance. 5. Marina Employees: Staff at marinas who fish recreationally and may assist boaters with fishing-related needs. | BQ8: Fish & Wildlife | BR8: https://dep.nj.gov/njfw/fishing/marine/saltwater-registry/ | BU8: Individual Registration | BV8: Data stored in another DEP-owned system
A9: Business Formation | B9: Department of the Treasury | C9: 140880 | D9: Yes this is a business/shop plurmit | F9: Yes - High Priority Integration | G9: Integrated | H9: Read and/or Write | R9: Division of Revenue and Enterprise Services | S9: Combined Data from 2018 and 2021 | T9: nj.gov/njbgs | U9: nj.gov/njbgs | V9: no | X9: In Person,Online,Mail,Phone,Email | Y9: In Person,Online,Mail,Email,Fax | Z9: NICUSA | AA9: 125 | AB9: 125 | AC9: Yes | AE9: No | AG9: No | AJ9: Yes | AK9: 2% (paper only) | AL9: Electronic, instantaneous; 5 business days, paper | AM9: Yes | AN9: No | AO9: Yes | AP9: 6 | AQ9: No | AR9: Yes | AS9: Yes | AT9: Incomplete/non-compliance with statutory/regualtory filing requirements | AU9: 9/1/2020-8/31/2021 | AV9: Yes | BH9: Yes | BK9: RL
A10: Business Registration (Integrates legal formation, tax registration and employer registration) | B10: Department of the Treasury | C10: 140544 | D10: Yes this is a business/shop plurmit | F10: Yes - High Priority Integration | G10: Partly integrated, we support validation not yet submission. | H10: Read | R10: Division of Revenue and Enterprise Services | S10: 2021 Permit List | T10: nj.gov/njbgs | U10: nj.gov/njbgs | V10: NJ REG | X10: In Person,Online,Mail,Phone,Email | Y10: In Person,Online,Mail,Email,Fax | Z10: NICUSA | AA10: 0 | AJ10: Yes | AK10: 2.5% (paper only) | AL10: Electronic, 2 business days; 10 business days, paper | AM10: Yes | AN10: No | AO10: Yes | AP10: 2.25 | AQ10: No | AR10: Yes | AS10: Yes | AT10: Incomplete/non-compliance with statutory/regualtory filing requirements | AU10: 8/26/2020 - 8/25/2021 | AV10: No | BH10: Yes | BK10: RL
A11: New Jersey S Corporation Business Tax Return | B11: Department of the Treasury | C11: 111701 | D11: Yes this is a business/shop plurmit | F11: Yes - Mention but not Integrate | G11: We would love to integrate but Treasury does not want to as of Aug 26 2024 | H11: Read | I11: https://dev.account.business.nj.gov/mgmt/cms#/collections/filings/entries/cbt-100s-final | R11: Division of Taxation | S11: 2021 Permit List | T11: https://nj.gov/treasury/taxation/prntcbt.shtml | U11: https://www.njportal.com/taxation/CBT | V11: CBT-100S | X11: Online | Y11: Online | Z11: DORES Web Portal & AXWAY (3rd party software vendor) | AJ11: Yes | AK11: Cannot provide rejection counts due to daily changes. | AL11: Instantaneous | AM11: Yes | AN11: No | AO11: Yes | AQ11: Yes | AR11: Yes | AS11: No | AT11: Registration, Data Integrity, Calculation | AU11: 2019 | AV11: No | BH11: Yes | BK11: RL
A12: Tentative Return and Application for Extension of Time to File Return | B12: Department of the Treasury | C12: 105458 | D12: Yes this is a business/shop plurmit | F12: Yes - Mention but not Integrate | H12: Read | I12: https://dev.account.business.nj.gov/mgmt/cms#/collections/filings/entries/cbt-200-t | R12: Division of Taxation | S12: 2021 Permit List | T12: https://nj.gov/treasury/taxation/prntcbt.shtml | U12: https://www1.state.nj.us/TYTR_BusinessFilings/jsp/common/Login.jsp?taxcode=20 | V12: CBT-200 | X12: Online | Y12: Online | Z12: DORES Web Portal & AXWAY (3rd party software vendor) | AI12: We already mention 100 and 100S in our system | AJ12: Yes | AK12: Cannot provide rejection counts due to daily changes. | AL12: Instantaneous | AM12: Yes | AN12: No | AO12: Yes | AQ12: Yes | AR12: Yes | AS12: No | AT12: Registration, Data Integrity, Calculation | AU12: 2019 | AV12: No | BH12: Yes | BK12: RL
A13: New Jersey Corporation Business Tax Return | B13: Department of the Treasury | C13: 104421 | D13: Yes this is a business/shop plurmit | F13: High Priority Integration, lacking agency buy-in | H13: Read | I13: https://dev.account.business.nj.gov/mgmt/cms#/collections/filings/entries/cbt-100_100u | R13: Division of Taxation | S13: 2021 Permit List | T13: https://nj.gov/treasury/taxation/prntcbt.shtml | U13: https://www.njportal.com/taxation/CBT | V13: CBT-100 | X13: Online | Y13: Online | Z13: DORES Web Portal & AXWAY (3rd party software vendor) | AJ13: Yes | AK13: Cannot provide rejection counts due to daily changes. | AL13: Instantaneous | AM13: Yes | AN13: No | AO13: Yes | AQ13: Yes | AR13: Yes | AS13: No | AT13: Registration, Data Integrity, Calculation | AU13: 2019 | AV13: No | BH13: Yes | BK13: RL
A14: Saltwater Angler - Review/Edit Current Registration | B14: Department of Environmental Protection | C14: 100000 | D14: No, this is for municipalities or residents but not businesses | E14: Submitted | F14: No | G14: Called two charter boat companies in NJ, and customers are covered under the Captain's Saltwater Registry - For Hire Vessel registry record - Also connected with Katie from the NJDEP - Fish & Wildlife and stated there are ~1050 for-hire registrations this year - Bait and tackle shop employees could fall under retail, but unclear if that means the owner of the shop needs this permit. Even if so, this seems like a rare use case. | H14: N/A | S14: Combined data from 2018 and 2021 | T14: https://www.nj.gov/dep/online/ | U14: https://www.nj.gov/dep/online/ | X14: Online | Y14: Online | Z14: DEP Online | AC14: No | AE14: No | AG14: No | AH14: https://www.nj.gov/dep/online/ | BP14: From site: The New Jersey Department of Environmental Protection established the New Jersey Saltwater Recreational Registry Program to exempt saltwater recreational anglers fishing in New Jersey’s marine and tidal waters from the federal registry and the $15.00 federal registration fee imposed in 2011. The Department of Environmental Protection (DEP) implemented the New Jersey Saltwater Recreational Registry Program (NJSRRP) effective May 4, 2011 through Administrative Order No. 2011-05 . Who Needs to Register? NOTE: Anglers with a valid registration with the National Saltwater Angler Registry or have a valid license from another exempted state are required to register (for free) with the NJ Saltwater Recreational Registry Program. Registration with NJ will exempt you from having to register with the National Saltwater Angler Registry. Individual saltwater anglers ages 16 and older MUST register if ANY of the following criteria are met: - Recreationally fish with a hand line or rod and line, spearfish or fish by hand - Recreationally fish in the marine and fresh tidal waters of the State of New Jersey - Recreationally fish in marine waters outside the State of New Jersey but land the catch in New Jersey Individual saltwater anglers are EXEMPT from registering if either of the following apply: - Under the age of 16 - Solely fish on for-hire (party and charter) vessels that are registered with the New Jersey Saltwater Recreational Registry Program For-hire vessel owners/operators MUST register if: - Carry individuals who engage in recreational fishing in the marine and fresh tidal waters of the State of New Jersey OR - Carry individuals who engage in recreational fishing in the marine waters outside the State of New Jersey but land their catch in New Jersey From chat GPT: In New Jersey, specific businesses require a Saltwater Angler registration to legally engage in saltwater fishing activities. These businesses include: 1. Charter Boats and Party Boats: Companies offering chartered fishing trips or party boat services where patrons pay to fish in New Jersey's marine and estuarine waters. 2. Tackle Shops: Retailers that sell fishing equipment and may provide guidance or services related to saltwater fishing. 3. Marinas: Facilities that offer boat docking, storage, and other services for recreational fishing vessels. 4. Fishing Guides: Professional guides who lead fishing expeditions for clients in saltwater areas. These businesses are required to register with the New Jersey Saltwater Recreational Registry Program to ensure they comply with state regulations and contribute to the management and conservation of marine resources. The registration helps the state monitor fishing activities and maintain sustainable fish populations. | BQ14: Fish & Wildlife | BR14: https://dep.nj.gov/njfw/fishing/marine/saltwater-registry/ | BU14: Individual Registration | BV14: Data stored in another DEP-owned system
A15: Bus Equipment (Safety Inspection Certs.) | B15: Motor Vehicle Commission | C15: 89030 | D15: Yes this is a business/shop plurmit | E15: Not | F15: Yes - Mention but not Integrate | G15: Not integrated since it is not an application, you call to schedule the inspection | H15: Mentioned | S15: Combined data from 2018 and 2021 | T15: No link | V15: SS-14 - CMC-12 -CMC12 | W15: N | X15: In person | Y15: In person | Z15: .Net or Java service or pdf acrobrat forms | AA15: $115(First recheck);$50(recheck);$70(recheck restoration) | AB15: $115(First recheck);$50(recheck);$70(recheck restoration) | AC15: Yes | AE15: No | AG15: No | AI15: Customer gets sticker.
A16: Individual and Business Major Line Renewal | B16: Department of Banking and Insurance | C16: 85930 | D16: Yes this is a business/shop plurmit | E16: Submitted | F16: No | G16: the renewal dates are automatically assigned and can vary depending on the users birthday month. This means we would need an integration in order to do this and have the correct expiration date | H16: No | S16: Combined data from 2018 and 2021 | U16: nipr.com | W16: Y | X16: Online | Y16: Mail,Online | AC16: No | AE16: No | AG16: No | AI16: INS
A17: Single Trip Permit (5 day) | B17: Department of Transportation | C17: 82341 | D17: Yes businesses often apply for this plurmit (for a device or project or something else) | E17: Submitted | F17: Yes - Mention but not Integrate | G17: Need further discussions on data partnership with agency before integration | H17: Mentioned | I17: https://dev.account.business.nj.gov/mgmt/cms#/collections/anytime-action-tasks-licenses/entries/single-trip-osow-permit | S17: Combined data from 2018 and 2021 | T17: https://nj.gotpermits.com | U17: https://nj.gotpermits.com | W17: Y | X17: Online | Y17: Online | Z17: Bentley Systems | AA17: $25.00 - $2000+ | AB17: $25.00 - $2000+ | AC17: Yes | AE17: No | AF17: Current online permit program available | AG17: Yes | AI17: Varies by size and weight
A18: Appointment Renewal (electronic only) | B18: Department of Banking and Insurance | C18: 78670 | D18: Yes, but primarily used by large businesses | E18: Submitted | F18: No | G18: out of scope for BizX, this is focused on large insurance companies | H18: No | S18: Combined data from 2018 and 2021 | T18: www.nipr.com | U18: https://pdb.nipr.com/ren/renUseAgree.jsp | W18: Y | X18: Online | Y18: Online | AC18: No | AE18: No | AG18: No | AI18: INS
A19: NJ Partnership Tax Extension to file NJ-CBT-1065 | B19: Department of the Treasury | C19: 75755 | D19: Yes this is a business/shop plurmit | F19: Yes - High Priority Integration | H19: Read | I19: https://dev.account.business.nj.gov/mgmt/cms#/collections/filings/entries/cbt-206 | R19: Division of Taxation | S19: 2021 Permit List | T19: https://nj.gov/treasury/taxation/prntpart.shtml | U19: https://www1.state.nj.us/TYTR_BusinessFilings/jsp/common/Login.jsp?taxcode=43 | V19: CBT-206 | X19: Online | Y19: In Person,Online,Mail | Z19: DORES Web Portal & AXWAY (3rd party software vendor) | AI19: Partnerships that are members of an entity electing to pay the Pass-Through Business Alternative Income Tax and that choose to apply the credit for their share of the tax to their nonresident partners tax must claim the credit on the NJ-CBT-1065. | AJ19: Yes | AK19: Cannot provide rejection counts due to daily changes. | AL19: Instantaneous | AM19: Yes | AN19: No | AO19: Yes | AQ19: Yes | AR19: Yes | AS19: No | AT19: Registration, Data Integrity, Calculation | AU19: 2019 | AV19: No | BH19: Yes | BK19: RL
A20: Boiler Inspection Certificates | B20: Department of Labor and Workforce Development | C20: 72794 | D20: Yes this is a business/shop plurmit | E20: Not | F20: Yes - Mention but not Integrate | G20: This will not be an integration, only a mention | H20: Mentioned | S20: Combined data from 2018 and 2021 | Y20: Mail,Email | AA20: Varies | AB20: Varies | AC20: Yes | AE20: No | AG20: No | AI20: https://www.nj.gov/labor/safetyandhealth/programs-services/boiler-pressure-vessel-compliance/ | BH20: Yes | BK20: RL | BL20: Get Your Boiler Registered and Inspected
A21: Vehicle Tile/Registration | B21: Motor Vehicle Commission | C21: 66018 | D21: Yes businesses often apply for this plurmit (for a device or project or something else) | E21: Not | F21: Yes - High Priority Integration | G21: Mentioned, integration in progress | H21: Mentioned
A22: Initial Resident & Nonresident Individual (Major Lines) | B22: Department of Banking and Insurance | C22: 62381 | D22: Yes this is a business/shop plurmit | E22: Submitted | F22: Yes - Mention but not Integrate | H22: Mentioned | S22: Combined data from 2018 and 2021 | T22: www.nipr.com | U22: nipr.com | W22: Y | X22: Online | Y22: Mail,Online | AC22: No | AE22: No | AG22: No | AI22: INS
A23: Emergency Trip Permit | B23: Division of Alcohol Division Control | C23: 60000 | D23: Yes this is a business/shop plurmit | F23: Yes - High Priority Integration | G23: The integration was added to account.Business.NJ.gov on 7/21/2025. This integration allows the user to enter the relevant data points in account.Businss.NJ.gov and to then submit the form which results in the data being sent via API to NICUSA (i.e. Tyler Technology) which consumes the data and returns the Permit for the user. | H23: Read and/or Write | J23: ADO 7863, ADO 14467, ADO 14936, ADO 15167, ADO 15204 | N23: Y | O23: Transportation and Warehousing | Q23: Y | U23: https://dev.account.business.nj.gov/actions/emergency-trip-permit | AA23: 30 | AB23: 30 | AH23: https://nj.accessgov.com/abc/Forms/Page/abc/emergencytrippermitshelp/0 | AI23: The integration was added to account.Business.NJ.gov on 7/21/2025. This integration allows the user to enter the relevant data points in account.Businss.NJ.gov and to then submit the form which results in the data being sent via API to NICUSA (i.e. Tyler Technology) which consumes the data and returns the Permit for the user. | BO23: Transportation and Warehousing | BT23: transportation
A24: Address Change | B24: Department of Banking and Insurance | C24: 58892 | E24: Submitted | F24: Unsure/need clarification | G24: need to align with SME | H24: No | S24: Combined data from 2018 and 2021 | W24: Y | X24: Online | Y24: Online | AA24: 50 | AB24: 50 | AC24: Yes | AE24: No | AG24: No | AI24: REC/Insurance
A25: CDL (Commercial Driver's License) | B25: Motor Vehicle Commission | C25: 53000 | D25: Yes businesses often apply for this plurmit (for a device or project or something else) | E25: Not | F25: Yes - High Priority Integration | G25: UX work done, needs to be implemented by dev. Potential to integrate | H25: No | K25: Evergreen
A26: International Registration Plan (IRP) | B26: Motor Vehicle Commission | C26: 52793 | D26: Yes businesses often apply for this plurmit (for a device or project or something else) | E26: Submitted | F26: Yes - Mention but not Integrate | G26: Need to discuss with SME if integration is possible | H26: Mentioned | S26: Combined data from 2018 and 2021 | T26: https://www.state.nj.us/mvc/pdf/commercial/irpqui1.pdf | V26: IRP-7/MCS-Irp-1,MCS-IRP-2 | W26: Y | X26: Mail,Online | Y26: Online | Z26: .Net or Java service or pdf acrobrat forms | AA26: Varies according to size and weight of vehicle | AB26: Varies according to size and weight of vehicle | AC26: Yes | AE26: No | AG26: No
A27: Salesperson - Renewal (2021-2023) | B27: Department of Banking and Insurance | C27: 49142 | D27: No, this is for municipalities or residents but not businesses | F27: No | H27: No | S27: 2021 Permit List | U27: https://www-dobi.state.nj.us/DOBI_RELOLSRV/LicenseeLogin | X27: Online | Y27: Mail | Z27: NJDOBI website | AA27: 301 | AJ27: 0 | AK27: 10 | AL27: 30 | AM27: 1 | AN27: 0 | AO27: 1 | AP27: 4 | AQ27: No | AR27: 1 | AS27: No | AT27: Non CE compliant | AV27: Yes
A28: New Jersey Partnership Return Corporation Business Tax | B28: Department of the Treasury | C28: 44811 | D28: Yes this is a business/shop plurmit | F28: High Priority Integration, lacking agency buy-in | H28: Read | I28: https://dev.account.business.nj.gov/mgmt/cms#/collections/filings/entries/nj-1065 | R28: Division of Taxation | S28: 2021 Permit List | T28: https://nj.gov/treasury/taxation/prntpart.shtml | U28: https://www1.state.nj.us/TYTR_BusinessFilings/jsp/common/Login.jsp?taxcode=43 | V28: NJ-CBT-1065 | X28: Online | Y28: In Person,Online,Mail | Z28: DORES Web Portal & AXWAY (3rd party software vendor) | AJ28: Yes | AK28: Cannot provide rejection counts due to daily changes. | AL28: Instantaneous | AM28: Yes | AN28: No | AO28: Yes | AQ28: Yes | AR28: Yes | AS28: No | AT28: Registration, Data Integrity, Calculation | AU28: 2019 | AV28: No | BH28: Yes | BK28: RL
A29: Pressure Vessel Inspection Certificates (includes refrigeration) | B29: Department of Labor and Workforce Development | C29: 43637 | D29: Yes this is a business/shop plurmit | E29: Not | F29: Yes - Mention but not Integrate | H29: Mentioned | S29: Combined data from 2018 and 2021 | Y29: Mail,Email | AA29: Varies | AB29: Varies | AC29: Yes | AE29: No | AG29: No | AI29: In New Jersey, the Bureau of Boiler and Pressure Vessel Compliance (BB&PVC) requires that pressure vessels, boilers, and refrigeration equipment be inspected at regular intervals https://www.nj.gov/labor/safetyandhealth/assets/PDFs/Boiler%20and%20Pressure%20Vessel%20Compliance/bbpvc_infoguide.pdf | BH29: Yes | BK29: RL
A30: Home Improvement Contractor (Renewal) | B30: Department of Law and Public Safety | C30: 42689 | D30: Yes this is a business/shop plurmit | F30: Yes - High Priority Integration | H30: Read | K30: Evergreen | R30: Division of Consumer Affairs | AI30: Renewal submission volume is an average of 2020-2024 | BD30: https://dev.account.business.nj.gov/mgmt/cms#/collections/license-calendar-events/entries/home-contractor | BH30: Yes | BL30: Home Improvement Contractor Renewal Deadline
A31: Employer Payroll Tax | B31: Department of the Treasury | C31: 42665 | D31: Yes this is a business/shop plurmit | F31: High Priority Integration, lacking agency buy-in | H31: Read | I31: https://dev.account.business.nj.gov/mgmt/cms#/collections/filings/entries/nj-927-h | R31: Division of Taxation | S31: 2021 Permit List | U31: https://www1.state.nj.us/TYTR_BusinessFilings/jsp/common/Login.jsp?taxcode=45 | V31: NJ927H | X31: Online | Y31: Online | Z31: DORES Web Portal & AXWAY (3rd party software vendor) | AJ31: Yes | AK31: Cannot provide rejection counts due to daily changes. | AL31: Instantaneous | AM31: Yes | AN31: No | AO31: Yes | AP31: DORES | AQ31: Yes | AR31: Yes | AS31: No | AT31: Registration, Data Integrity, Calculation | AU31: 2020 | AV31: No | BH31: Yes | BK31: RL
A32: Streamlined Sales Tax | B32: Department of the Treasury | C32: 42560 | D32: Yes this is a business/shop plurmit | F32: High Priority Integration, lacking agency buy-in | G32: Mentioned on the register for taxes page on 9/18/2025 | H32: Mentioned | R32: Division of Taxation | S32: 2021 Permit List | U32: https://www2-tre.mwg.state.nj.us/TYTR_SSTP_WS/EFileService.asmx | V32: SST-50 | Y32: Online | Z32: SST Web Services Portal | AI32: https://www.streamlinedsalestax.org/Shared-Pages/faqs/faqs---about-streamlined | AJ32: Yes | AK32: Cannot provide rejection counts due to daily changes. | AL32: Instantaneous | AM32: Yes | AN32: No | AO32: Yes | AP32: DORES | AQ32: Yes | AR32: Yes | AS32: No | AT32: Registration, Data Integrity, Calculation | AU32: 2020 | AV32: No | BH32: Yes | BK32: RL
A33: Registered Representative-Agent (Bureau of Securities) | B33: Department of Law and Public Safety | C33: 38000 | D33: Yes, but primarily used by large businesses | E33: Submitted | F33: No | G33: Not pursuing this as it's for larger businesses, confirmed w Dillon | H33: No | S33: Combined data from 2018 and 2021 | T33: http://www.finra.org/file/form-u4-uniform-application-securities-industry-registration-or-transfer | U33: https://crd.finra.org | V33: Form U4 | W33: Y | X33: Online | Y33: Online | Z33: FINRA Web CRD (Central Registration Depository) | AA33: 60 | AB33: 60 | AC33: Yes | AD33: FINRA | AE33: Yes | AG33: No | AI33: may be technically individual: "an individual who is licensed to sell securities and has the legal power of an agent in the United States." - Wikipedia | BH33: Yes | BK33: RL
A34: Urban Enterprise Zone Sales Tax | B34: Department of the Treasury | C34: 37350 | D34: Yes this is a business/shop plurmit | F34: High Priority Integration, lacking agency buy-in | H34: Read | I34: https://dev.account.business.nj.gov/mgmt/cms#/collections/filings/entries/uz-50 | R34: Division of Taxation | S34: 2021 Permit List | U34: https://www1.state.nj.us/TYTR_BusinessFilings/jsp/common/Login.jsp?taxcode=11 | V34: UZ-50; UZ-50B | X34: Online | Y34: Online | Z34: DORES Web Portal | AJ34: Yes | AK34: Cannot provide rejection counts due to daily changes. | AL34: Instantaneous | AM34: Yes | AN34: No | AO34: Yes | AP34: DORES | AQ34: Yes | AR34: Yes | AS34: No | AT34: Registration, Data Integrity, Calculation | AU34: 2020 | AV34: No | BH34: Yes | BK34: RL
A35: Notary Public | B35: Department of the Treasury | C35: 32000 | D35: No, but certain employees need this license, and businesses might want to be aware of that/look up* | E35: Submitted | F35: Yes - Mention but not Integrate | H35: Mentioned | R35: Division of Revenue and Enterprise Services | S35: Combined data from 2018 and 2021 | T35: nj.gov/njbgs | U35: nj.gov/njbgs | W35: Y | X35: Online | Y35: Online | Z35: NICUSA | AA35: 50 | AB35: 50 | AC35: Yes | AE35: No | AG35: No | BH35: Yes | BK35: RL | BL35: Register as a Notary Public
A36: Drinking Water (eDWR) | B36: Department of Environmental Protection | C36: 29458 | D36: No, this is for municipalities or residents but not businesses | E36: Submitted | F36: No | G36: Based on NJ A.C. 7:10-5.4 requirements: - The submission of Drinking Water reports is primarily the responsibility of municipal water supply systems. - The submission of this type of report could be leveraged by a business that may not be connected to the local water supply and constructed/connected to an on-site well system, which mainly impacts rural-based businesses in NJ. - It seems like a super niche scenario that can span across all industries that are constructing a facility (not home-based) and operation that would provide drinking water to employees or customers. From Mike Matsko (DEP DataMiner App Owner) "Regarding the Ask, all drinking water data is made available in a separate application called Drinking Water Watch - There are some drinking water reports on DataMiner but none that show the monitoring results. - My understanding is that only Water Systems that provide water to the public report this data. If they don't submit they are issued a violation." Summary of Drinking Water Act - Both locations have active wells - Corbin Cafe Drinking Water Report & Hot Dog Johnnys Drinking Water Report Richard.Gunosky@dep.nj.gov is DWR Data POC in DEP Export of Drinking Water Watch - Systems across NJ Prioritization Rationale: We should focus on this later: - The possibility of a small-to-medium-sized business coming through B.NJ.gov + on a well and serving employees/customers is not a large pool. SBAB stated that many new businesses are located where they would connect to municipal water systems. - The majority of DWR submissions are coming from the larger entities (city/town water systems) since they must report DWR reports monthly. County Environmental Health Assoc. (PWSID) --> will require facilities to report their water quality reports | H36: N/A | S36: Combined data from 2018 and 2021 | T36: https://www.nj.gov/dep/online/ | U36: https://www.nj.gov/dep/online/ | X36: Online | Y36: Online | Z36: DEP Online | AC36: No | AE36: No | AG36: No | AH36: https://www.nj.gov/dep/online/ | BP36: From DEP User Guide: The New Jersey Electronic Environmental Reporting System (E2) is a web-based information system that allows the regulated community to electronically submit reports to the Department of Environmental Protection (NJDEP). - The E2 system provides an alternative to submitting hand-written or paper-based reports that is faster, more efficient, and requires less processing for water systems and the NJDEP. - As a fully operational electronic reporting system, all of the necessary legal, security, and electronic signature functionalities have been included to serve as a completely paperless reporting system. Currently, the E2 system allows laboratories to submit three major categories of reports: - Electronic Drinking Water Reports (DWR) - Electronic New Jersey Quantitation Limit (NJQL) reports - Electronic Private Well Testing Act (PWTA) Reports Currently, the E2 system allows water systems to perform the following major functions: - View Electronic Drinking Water Reports (DWR) containing analytical results submitted by laboratories on behalf of water systems - Submit the Annual Water Utilization report The Bureau of Safe Drinking Water has not made all forms available for electronic submission. Therefore, a water system may need to submit Drinking Water data electronically for some reports and use paper for other reports. | BQ36: Water Supply | BR36: https://www.nj.gov/dep/online/e2/NJ_E2_v1.3_DWR_Users_Guide.pdf | BT36: health-club,restaurant,daycare,lodging | BU36: Report/Logbook | BV36: Data stored in another DEP-owned system | BW36: My business will have its own well for water supply that has at least 15 service connections. ,My business regularly serves an average of at least 25 individuals daily for at least 60 days out of the year. ,My business will be drilling wells.
A37: Drinking Water Reports (DWR) | B37: Department of Environmental Protection | C37: 29456 | D37: No | E37: Submitted | F37: No | G37: Based on NJ A.C. 7:10-5.4 requirements: - The submission of Drinking Water reports is primarily the responsibility of municipal water supply systems. - The submission of this type of report could be leveraged by a business that may not be connected to the local water supply and constructed/connected to an on-site well system; which mainly impacts rural-based businesses in NJ. - It seems like a super niche scenario that can span across all industries that are constructing a facility (not home-based) and operation that would provide drinking water to employees or customers. From Mike Matsko (DEP DataMiner App Owner) "Regarding the Ask, all drinking water data is made available in a separate application called Drinking Water Watch - There are some drinking water reports on DataMiner but none that show the monitoring results. - My understanding is that only Water Systems that provide water to the public report this data. If they don't submit they are issued a violation." Summary of Drinking Water Act - Both locations have active wells - Corbin Cafe Drinking Water Report & Hot Dog Johnnys Drinking Water Report Richard.Gunosky@dep.nj.gov is DWR Data POC in DEP Export of Drinking Water Watch - Systems across NJ | H37: N/A | S37: Combined data from 2018 and 2021 | T37: www.njdeponline.com | X37: Online | Y37: Online | Z37: Regulatory Service Portal (njdeponline) | AC37: No | AE37: No | AG37: No | AH37: Guidance documents provided when requested | BP37: Based on a call with the Water Supply Director, this is a dupe record from the data dump in 2018/2021. All E2 reports (DWRs) are submitted electronically | BQ37: Water Supply | BT37: health-club,restaurant | BU37: Report/Logbook | BV37: Data stored in another DEP-owned system
A38: Weights and Measures Device Registration Certification (Business) | B38: Department of Law and Public Safety | C38: 26609 | D38: Yes businesses often apply for this plurmit (for a device or project or something else) | E38: Available | F38: High Priority Integration, lacking agency buy-in | H38: Mentioned | S38: Combined data from 2018 and 2021 | T38: https://www.njconsumeraffairs.gov/OWM/Applications/Registration-Application-for-Commercial-Weighing-and-Measuring-Devices.pdf | W38: N | X38: In person,Mail,Online | Y38: In person,Mail | Z38: DCA Website | AA38: $- | AC38: No | AE38: No | AG38: No | BH38: Yes | BK38: RL | BL38: "weights-measures-registration - Register a Scale, Meter, or Other Weighing and Measuring Device for Your Business"
A39: Code 23 Oversize/Overweight Permit (30 day) | B39: Department of Transportation | C39: 23872 | D39: Yes businesses often apply for this plurmit (for a device or project or something else) | E39: Submitted | F39: Yes - Mention but not Integrate | G39: Need further discussions and data partnership with agency before integration | H39: Mentioned | I39: https://dev.account.business.nj.gov/mgmt/cms#/collections/anytime-action-tasks-licenses/entries/code23-osow-30day-permit_1?ref=workflow | S39: Combined data from 2018 and 2021 | T39: https://nj.gotpermits.com | U39: https://nj.gotpermits.com | W39: Y | X39: Online | Y39: Online | Z39: Bentley Systems | AA39: 12.6 | AB39: 12.6 | AC39: Yes | AE39: No | AF39: Current online permit program available | AG39: Yes
A40: Referral Agent - Renewal (2021-2023) | B40: Department of Banking and Insurance | C40: 23247 | D40: No, this is for municipalities or residents but not businesses | F40: No | H40: No | S40: 2021 Permit List | U40: https://www-dobi.state.nj.us/DOBI_RELOLSRV/LicenseeLogin | X40: Online | Y40: Online | Z40: NJDOBI website | AA40: 100 | AJ40: 0 | AK40: 0 | AL40: 30 | AM40: 1 | AN40: 0 | AO40: 1 | AP40: 4 | AQ40: No | AR40: 1 | AS40: No | AV40: Yes
...

Sheet Counting - no filter on "busine
A1: Department | B1: Number of Licenses | C1: Annual Submission
A2: Board of Public Utilities | B2: =COUNTIF('Plurmits-All Plurmits'!B:B, A2) -> 5 | C2: =SUMIF('Plurmits-All Plurmits'!B:B, A2, 'Plurmits-All Plurmits'!C:C) -> 697
A3: Casino Control Commission | B3: =COUNTIF('Plurmits-All Plurmits'!B:B, A3) -> 1 | C3: =SUMIF('Plurmits-All Plurmits'!B:B, A3, 'Plurmits-All Plurmits'!C:C) -> 14094
A4: Department of Agriculture | B4: =COUNTIF('Plurmits-All Plurmits'!B:B, A4) -> 31 | C4: =SUMIF('Plurmits-All Plurmits'!B:B, A4, 'Plurmits-All Plurmits'!C:C) -> 22074
A5: Department of Banking and Insurance | B5: =COUNTIF('Plurmits-All Plurmits'!B:B, A5) -> 210 | C5: =SUMIF('Plurmits-All Plurmits'!B:B, A5, 'Plurmits-All Plurmits'!C:C) -> 876362
A6: Department of Children and Families | B6: =COUNTIF('Plurmits-All Plurmits'!B:B, A6) -> 12 | C6: =SUMIF('Plurmits-All Plurmits'!B:B, A6, 'Plurmits-All Plurmits'!C:C) -> 4991
A7: Department of Community Affairs | B7: =COUNTIF('Plurmits-All Plurmits'!B:B, A7) -> 116 | C7: =SUMIF('Plurmits-All Plurmits'!B:B, A7, 'Plurmits-All Plurmits'!C:C) -> 98450
A8: Department of Education | B8: =COUNTIF('Plurmits-All Plurmits'!B:B, A8) -> 149 | C8: =SUMIF('Plurmits-All Plurmits'!B:B, A8, 'Plurmits-All Plurmits'!C:C) -> 36845
A9: Department of Environmental Protection | B9: =COUNTIF('Plurmits-All Plurmits'!B:B, A9) -> 800 | C9: =SUMIF('Plurmits-All Plurmits'!B:B, A9, 'Plurmits-All Plurmits'!C:C) -> 751422
A10: Department of Health | B10: =COUNTIF('Plurmits-All Plurmits'!B:B, A10) -> 116 | C10: =SUMIF('Plurmits-All Plurmits'!B:B, A10, 'Plurmits-All Plurmits'!C:C) -> 68750
A11: Department of Labor and Workforce Development | B11: =COUNTIF('Plurmits-All Plurmits'!B:B, A11) -> 38 | C11: =SUMIF('Plurmits-All Plurmits'!B:B, A11, 'Plurmits-All Plurmits'!C:C) -> 150722
A12: Department of Law and Public Safety | B12: =COUNTIF('Plurmits-All Plurmits'!B:B, A12) -> 564 | C12: =SUMIF('Plurmits-All Plurmits'!B:B, A12, 'Plurmits-All Plurmits'!C:C) -> 494145
A13: Department of the Treasury | B13: =COUNTIF('Plurmits-All Plurmits'!B:B, A13) -> 81 | C13: =SUMIF('Plurmits-All Plurmits'!B:B, A13, 'Plurmits-All Plurmits'!C:C) -> 3093782
... A16: Motor Vehicle Commission | B16: =COUNTIF('Plurmits-All Plurmits'!B:B, A16) -> 42 | C16: =SUMIF('Plurmits-All Plurmits'!B:B, A16, 'Plurmits-All Plurmits'!C:C) -> 317751
C17: =SUMIF('Plurmits-All Plurmits'!B:B, A17, 'Plurmits-All Plurmits'!C:C) -> 0
B18: =SUM(B2:B17) -> 2185 | C18: =SUMIF('Plurmits-All Plurmits'!B:B, A18, 'Plurmits-All Plurmits'!C:C) -> 0

Sheet Pivot - filtered to business
A1: Does this plurmit apply to businesses? | B1: (Multiple Items)
A4: Department | B4: SUM of Annual volume of submissions | C4: COUNT of Annual volume of submissions
A5: Casino Control Commission | B5: 14094 | C5: 1
A6: Department of Banking and Insurance | B6: 696576 | C6: 5
A7: Department of Community Affairs | B7: 65604 | C7: 43
A8: Department of Environmental Protection | B8: 158335 | C8: 91
A9: Department of Labor and Workforce Development | B9: 132969 | C9: 6
A10: Department of Law and Public Safety | B10: 397107 | C10: 125
A11: Department of the Treasury | B11: 3058257 | C11: 63
A12: Department of Transportation | B12: 118905 | C12: 6
A13: Division of Alcohol Division Control | B13: 63365 | C13: 2
A14: Motor Vehicle Commission | B14: 307063 | C14: 11
A15: Grand Total | B15: 5012275 | C15: 353
